Workbook

Sheet README & Disclosure
A1: MAL-FRT-001 — GRC Findings & Remediation Tracker
A2: SIMULATED GRC PRACTICE ENVIRONMENT — All findings, observations, planning gaps, statuses, target dates and assessment results in this workbook belong to a simulated portfolio scenario (MindfulAI Labs). They do not represent verified production-system testing, actual evidence, management approvals, or an actual organization.
A3: MindfulAI Labs · Simulated GRC Practice Environment · AI GRC & Control Assurance Portfolio
A5: Document Control
A6: Document ID | B6: MAL-FRT-001
A7: Document Title | B7: GRC Findings & Remediation Tracker
A8: Version | B8: 1.0
A9: Prepared By | B9: Maxine Jones, GRC Analyst
A10: Prepared Date | B10: October 21, 2026
A11: Classification | B11: Confidential — Internal Use Only
A12: Status | B12: Final — Portfolio Simulation
A13: Purpose and Basis
A14: Purpose | B14: Consolidates the documented findings, process-improvement observations, planning gaps, remediation actions and evidence requirements from ten MindfulAI Labs control artifacts (MAL-CHK-001 through MAL-VRA-010) into one filterable tracker.
A15: Basis | B15: Built exclusively from the ten MAL-xxx source documents and the six JSON exports (Asset Register, Risk Register, Control Register, Policies, Risk Appetite Statements, KRIs). Nothing here was drawn from outside those sources.
A16: Simulation disclosure | B16: SIMULATED GRC PRACTICE ENVIRONMENT — All findings, observations, planning gaps, statuses, target dates and assessment results in this workbook belong to a simulated portfolio scenario (MindfulAI Labs). They do not represent verified production-system testing, actual evidence, management approvals, or an actual organization.
A17: What this tracker does NOT contain | B17: No invented findings, remediation actions, completion dates, management approvals, evidence, closure results, residual risk scores or risk-tolerance conclusions. No suggested closure criteria. Every sign-off table in the source documents is blank; no approvals are represented here.
A18: Record Classifications (Findings tab)
A19: Confirmed Finding (Simulated) | B19: A control deficiency or exception that the source document explicitly records as a finding or exception within the simulated scenario (ACR-xx, VUL-01/02, PRV-01/02, LOG-01/02, VRA-01/02/03).
A20: Observation | B20: A source-labelled observation: process-improvement observations (OBS-01, VUL-03, PRV-03, LOG-03, VRA-04), risk-register coverage gaps, and one asset-register observation. The source states these are not control exceptions.
A21: Planning Gap | B21: A pre-assessment planning observation (APO-01 to APO-04) in MAL-CAP-009. The source states these are not findings and not control deficiencies; no testing was performed.
A22: Evidence Requirement | B22: An item marked “Evidence Required — Not Provided (Simulated Requirement)”. Kept on its own tab. A missing-evidence item is NOT a control deficiency and is never counted as one.
A23: Reported Status vs. Validated Closure
A24: Rule | B24: “Status (As Documented)” is the status stated in the source document. “Independent Closure Validation” is a separate field. No remediation status in this tracker has been independently validated: every record reads “Not performed — evidence not provided”. The one reported remediation (ACR-03, “Remediated (Simulated) — account disabled; underlying process fix Open”) is preserved as written and is NOT counted as closed.
A25: Analyst-derived fields | B25: Columns whose header ends “(Analyst-Derived)” — Severity Group, Primary Owner Team, Reported Status Group — are reporting classifications added for filtering and dashboard counts only. The original wording is always kept in the adjacent “(As Documented)” column.
A26: Target dates | B26: Exact dates are stored as dates. Quarterly targets (e.g., Q4 2026, Q1 2027) are kept as text; no calendar deadline has been assigned to them. “Not stated in source” means the source gives no date.
A27: Closure criteria | B27: Taken verbatim from the source “Validation” statement where one exists. Otherwise “Not Defined in Source”.
A28: Tabs
A29: Summary Dashboard | B29: Formula-driven counts by classification, severity group, status, source document, owner and target timeline; reported vs. validated closure; contextual KRI / risk-appetite / policy references.
A30: Findings | B30: 29 trackable records with source traceability (document, section, original ID).
A31: Remediation Actions | B31: 30 actions, one per source recommendation (ACR-03 is split in two because the source reports two different statuses).
A32: Evidence Requests | B32: 83 evidence requirements, separate from findings.
A33: Source Index | B33: The ten source documents, with documented counts reconciled to extracted counts.
A34: ID Crosswalk | B34: Source IDs ↔ normalized IDs for assets, risks and controls; policy references. Normalized IDs are shown only where a source document states them.
A35: Data Dictionary | B35: Every column, its allowed values and where its content comes from.
A36: Scope Notes
A37: Excluded: MAL-IPR-011 | B37: The assessment document for control A.5.35 (independent peer review; Not Tested in the Control Register) was not provided, so it contributes no findings, actions or evidence. The control appears in the ID Crosswalk only.
A38: Not logged as findings | B38: Items the sources mark as Met / Passed; blank sign-off tables; scope notes (e.g., assets excluded or deferred to program level in MAL-VMA-005, MAL-BRT-007, MAL-LMA-008); the assessor-independence consideration in MAL-CAP-009; and risk-appetite / KRI context.
A39: Risk appetite and KRIs | B39: Used as context only where a source document cites them. No residual risk scores are stated or computed, and no comparison to risk tolerance is made.
A40: Reconciliation (live formulas)
A41: Trackable records (Findings tab) | B41: =COUNTA(Findings!$A$5:$A$33) -> 29 | C41: Expected 29
...

Sheet Summary Dashboard
A1: Summary Dashboard
A2: SIMULATED GRC PRACTICE ENVIRONMENT — All findings, observations, planning gaps, statuses, target dates and assessment results in this workbook belong to a simulated portfolio scenario (MindfulAI Labs). They do not represent verified production-system testing, actual evidence, management approvals, or an actual organization.
A3: All figures are live formulas over the Findings, Remediation Actions, Evidence Requests and Source Index tabs.
A5: As-of date (editable input) | B5: 46316 | C5: Assumption: set to the preparation date (2026-10-21). Change it to re-run the target-date counts in section 6.
A7: 1. Record counts
A8: Measure | B8: Count
A9: Confirmed Findings (Simulated) | B9: =COUNTIF(Findings!$L$5:$L$33,"Confirmed Finding (Simulated)") -> 12
A10: Observations | B10: =COUNTIF(Findings!$L$5:$L$33,"Observation") -> 13
A11: Planning Gaps | B11: =COUNTIF(Findings!$L$5:$L$33,"Planning Gap") -> 4
A12: Total trackable records (Findings tab) | B12: =SUM(B9:B11) -> 29
A13: Remediation actions (Remediation Actions tab) | B13: =COUNTA('Remediation Actions'!$A$5:$A$34) -> 30
A14: Evidence requirements (separate from findings) | B14: =COUNTA('Evidence Requests'!$A$5:$A$87) -> 83
A15: Evidence requirements treated as control deficiencies | B15: =COUNTIF('Evidence Requests'!$M$5:$M$87,"Yes*") -> 0
A17: 2. Reported simulated status vs. independently validated closure
A18: Measure | B18: Records | C18: Remediation Actions
A19: Reported: In Progress (Simulated) | B19: =COUNTIF(Findings!$T$5:$T$33,"In Progress (Simulated)") -> 8 | C19: =COUNTIF('Remediation Actions'!$J$5:$J$34,"In Progress (Simulated)") -> 8
A20: Reported: Open (Simulated) | B20: =COUNTIF(Findings!$T$5:$T$33,"Open (Simulated)") -> 10 | C20: =COUNTIF('Remediation Actions'!$J$5:$J$34,"Open (Simulated)") -> 11
A21: Reported: Reported Remediated (Sim.) — Process Fix Open | B21: =COUNTIF(Findings!$T$5:$T$33,"Reported Remediated (Sim.) — Process Fix Open") -> 1 | C21: =COUNTIF('Remediation Actions'!$J$5:$J$34,"Reported Remediated (Sim.) — Process Fix Open") -> 0
A22: Reported: Accepted by Owner (per source) | B22: =COUNTIF(Findings!$T$5:$T$33,"Accepted by Owner (per source)") -> 1 | C22: =COUNTIF('Remediation Actions'!$J$5:$J$34,"Accepted by Owner (per source)") -> 1
A23: Reported: No Status in Source | B23: =COUNTIF(Findings!$T$5:$T$33,"No Status in Source") -> 9 | C23: =COUNTIF('Remediation Actions'!$J$5:$J$34,"No Status in Source") -> 9
A24: Reported: Remediated (Simulated) — account disabled (ACR-03 action split) | B24: n/a | C24: =COUNTIF('Remediation Actions'!$J$5:$J$34,"Reported Remediated (Simulated)") -> 1
A25: Total (reconciles to section 1) | B25: =SUM(B19:B23) -> 29 | C25: =SUM(C19:C24) -> 30
A26: Independently validated closures | B26: =COUNTIF(Findings!$U$5:$U$33,"Validated*") -> 0 | C26: =COUNTIF('Remediation Actions'!$O$5:$O$34,"Validated*") -> 0 | D26: Zero: no closure evidence exists in the simulated scenario
A27: Independent closure validation NOT performed | B27: =COUNTIF(Findings!$U$5:$U$33,"Not performed*") -> 29 | C27: =COUNTIF('Remediation Actions'!$O$5:$O$34,"Not performed*") -> 30
A29: 3. Severity group (analyst-derived) by classification — original severity wording is on the Findings tab
A30: Severity Group (Analyst-Derived) | B30: Confirmed Findings | C30: Observations | D30: Planning Gaps | E30: Total
A31: High | B31: =COUNTIFS(Findings!$O$5:$O$33,"High",Findings!$L$5:$L$33,"Confirmed Finding (Simulated)") -> 2 | C31: =COUNTIFS(Findings!$O$5:$O$33,"High",Findings!$L$5:$L$33,"Observation") -> 0 | D31: =COUNTIFS(Findings!$O$5:$O$33,"High",Findings!$L$5:$L$33,"Planning Gap") -> 0 | E31: =SUM(B31:D31) -> 2
A32: Medium-High | B32: =COUNTIFS(Findings!$O$5:$O$33,"Medium-High",Findings!$L$5:$L$33,"Confirmed Finding (Simulated)") -> 1 | C32: =COUNTIFS(Findings!$O$5:$O$33,"Medium-High",Findings!$L$5:$L$33,"Observation") -> 0 | D32: =COUNTIFS(Findings!$O$5:$O$33,"Medium-High",Findings!$L$5:$L$33,"Planning Gap") -> 0 | E32: =SUM(B32:D32) -> 1
A33: Medium | B33: =COUNTIFS(Findings!$O$5:$O$33,"Medium",Findings!$L$5:$L$33,"Confirmed Finding (Simulated)") -> 9 | C33: =COUNTIFS(Findings!$O$5:$O$33,"Medium",Findings!$L$5:$L$33,"Observation") -> 0 | D33: =COUNTIFS(Findings!$O$5:$O$33,"Medium",Findings!$L$5:$L$33,"Planning Gap") -> 0 | E33: =SUM(B33:D33) -> 9
A34: Low | B34: =COUNTIFS(Findings!$O$5:$O$33,"Low",Findings!$L$5:$L$33,"Confirmed Finding (Simulated)") -> 0 | C34: =COUNTIFS(Findings!$O$5:$O$33,"Low",Findings!$L$5:$L$33,"Observation") -> 8 | D34: =COUNTIFS(Findings!$O$5:$O$33,"Low",Findings!$L$5:$L$33,"Planning Gap") -> 0 | E34: =SUM(B34:D34) -> 8
A35: Not Rated | B35: =COUNTIFS(Findings!$O$5:$O$33,"Not Rated",Findings!$L$5:$L$33,"Confirmed Finding (Simulated)") -> 0 | C35: =COUNTIFS(Findings!$O$5:$O$33,"Not Rated",Findings!$L$5:$L$33,"Observation") -> 5 | D35: =COUNTIFS(Findings!$O$5:$O$33,"Not Rated",Findings!$L$5:$L$33,"Planning Gap") -> 4 | E35: =SUM(B35:D35) -> 9
A36: Total | B36: =SUM(B31:B35) -> 12 | C36: =SUM(C31:C35) -> 13 | D36: =SUM(D31:D35) -> 4 | E36: =SUM(E31:E35) -> 29
A38: 4. By source document and control rating
A39: Source Document | B39: Control Rating (Source) | C39: Findings | D39: Observations | E39: Planning Gaps | F39: Evidence Requirements | G39: Reconciliation
A40: ='Source Index'!A5&" — "&'Source Index'!B5 -> MAL-CHK-001 — AI Training Data Validation Checklist | B40: ='Source Index'!H5 -> Effective | C40: ='Source Index'!N5 -> 0 | D40: ='Source Index'!O5 -> 1 | E40: ='Source Index'!P5 -> 0 | F40: ='Source Index'!Q5 -> 5 | G40: ='Source Index'!R5 -> Match
A41: ='Source Index'!A6&" — "&'Source Index'!B6 -> MAL-ACR-002 — User Access Review Worksheet | B41: ='Source Index'!H6 -> Partially Effective | C41: ='Source Index'!N6 -> 3 | D41: ='Source Index'!O6 -> 0 | E41: ='Source Index'!P6 -> 0 | F41: ='Source Index'!Q6 -> 6 | G41: ='Source Index'!R6 -> Match
A42: ='Source Index'!A7&" — "&'Source Index'!B7 -> MAL-CTW-003 — Change Management Control Test Worksheet | B42: ='Source Index'!H7 -> Effective | C42: ='Source Index'!N7 -> 0 | D42: ='Source Index'!O7 -> 1 | E42: ='Source Index'!P7 -> 0 | F42: ='Source Index'!Q7 -> 7 | G42: ='Source Index'!R7 -> Match
A43: ='Source Index'!A8&" — "&'Source Index'!B8 -> MAL-STD-004 — Privileged Access & Multi-Factor Authentication Security Standard | B43: ='Source Index'!H8 -> Effective | C43: ='Source Index'!N8 -> 0 | D43: ='Source Index'!O8 -> 1 | E43: ='Source Index'!P8 -> 0 | F43: ='Source Index'!Q8 -> 9 | G43: ='Source Index'!R8 -> Match
A44: ='Source Index'!A9&" — "&'Source Index'!B9 -> MAL-VMA-005 — Vulnerability Management Control Assessment / Test Report | B44: ='Source Index'!H9 -> Partially Effective | C44: ='Source Index'!N9 -> 2 | D44: ='Source Index'!O9 -> 2 | E44: ='Source Index'!P9 -> 0 | F44: ='Source Index'!Q9 -> 7 | G44: ='Source Index'!R9 -> Match
A45: ='Source Index'!A10&" — "&'Source Index'!B10 -> MAL-PIA-006 — AI Privacy Impact Assessment (DPIA-Aligned) | B45: ='Source Index'!H10 -> Partially Effective | C45: ='Source Index'!N10 -> 2 | D45: ='Source Index'!O10 -> 2 | E45: ='Source Index'!P10 -> 0 | F45: ='Source Index'!Q10 -> 7 | G45: ='Source Index'!R10 -> Match
...

Sheet Findings
A1: Findings, Observations & Planning Gaps
A2: SIMULATED GRC PRACTICE ENVIRONMENT — All findings, observations, planning gaps, statuses, target dates and assessment results in this workbook belong to a simulated portfolio scenario (MindfulAI Labs). They do not represent verified production-system testing, actual evidence, management approvals, or an actual organization.
A3: One row per trackable record. Original wording is preserved in “(As Documented)” columns; “(Analyst-Derived)” columns are reporting classifications only.
A4: Tracker ID | B4: Original Source ID | C4: Source Document ID | D4: Source Document Title | E4: Source Section | F4: Related Control | G4: Control Rating (Source Register) | H4: Related Asset | I4: Related Risk | J4: Title (As Documented) | K4: Description (As Documented) | L4: Classification | M4: Subtype | N4: Severity (As Documented) | O4: Severity Group (Analyst-Derived) | P4: Owner (As Documented) | Q4: Primary Owner Team (Analyst-Derived) | R4: Recommended Action (As Documented) | S4: Status (As Documented) | T4: Reported Status Group (Analyst-Derived) | U4: Independent Closure Validation | V4: Target Date (As Documented) | W4: Target Date (Exact) | X4: Target Date Type | Y4: Evidence Required (Cross-Reference) | Z4: Closure Criteria | AA4: Rating Impact (As Documented) | AB4: Simulation Flag
A5: FRT-001 | B5: OBS-01 | C5: MAL-CHK-001 | D5: AI Training Data Validation Checklist | E5: §6 | F5: CTL-mu0tgvxq — Perform documented bias and data quality validation before AI model approval (ISO 27001 A.5.12) | G5: Effective | H5: AST-002 (source ID AST-mu0set5n) — Financial Risk Training Data Repository | I5: RSK-mu0sxjrj (RSK-001) — Training data bias causes inaccurate clinical AI recommendations (source: this checklist supports data-level bias validation and does not, on its own, close that risk) | J5: OBS-01 — Field Completeness (Minor) | K5: Approximately 0.4% of records contained a missing value in a non-critical, optional field. (Simulated sample figure.) | L5: Observation | M5: Minor Observation (source label) | N5: Not separately rated; Risk / Impact: Low | O5: Low | P5: Data Science Team | Q5: Data Science Team | R5: Continue monitoring field completeness in future quarterly validations and confirm the field remains excluded from model input. | S5: Records retained; reviewed and accepted by the Data Science Team | T5: Accepted by Owner (per source) | U5: Not performed — evidence not provided | V5: Not stated in source | X5: Not stated in source | Y5: Control-level evidence list EVD-001 to EVD-005 (Evidence Requests tab); the source does not map items to this record | Z5: Not Defined in Source | AA5: This observation is minor and does not change the Effective conclusion for the control. | AB5: Simulated portfolio scenario
A6: FRT-002 | B6: ACR-01 | C6: MAL-ACR-002 | D6: User Access Review Worksheet | E6: §8–9 | F6: CTL-mu1nugzu — Restrict AI training data repositories to authorized personnel using role-based access (NIST CSF PR.AA-05) | G6: Partially Effective | H6: AST-002 (source ID AST-mu0set5n) — Financial Risk Training Data Repository | I6: RSK-mu0t1uva (RSK-002) — Unauthorized user exploits inadequate data access restrictions causing sensitive data exposure to Financial Risk Training Data Repository | J6: ACR-01 — Outdated Access Following a Role Change (Mover) | K6: Generic test identity U-1043 transferred out of the Analytics function but retained read/write (FRTDR-DataEngineer) access to the repository beyond the effective date of the role change. (Simulated.) | L6: Confirmed Finding (Simulated) | M6: Control Deficiency (Exception) | N6: Medium | O6: Medium | P6: IAM Team (execution), with Data Science Team (resource-owner approval) | Q6: IAM Team | R6: Revoke the retained entitlements and incorporate mover events into the joiner/mover/leaver (JML) process, with HR-triggered, automated recalculation of access on role change. | S6: In Progress (Simulated) | T6: In Progress (Simulated) | U6: Not performed — evidence not provided | V6: October 31, 2026 (Simulated) | W6: 46326 | X6: Exact date | Y6: Control-level evidence list EVD-006 to EVD-011 (Evidence Requests tab); the source does not map items to this record | Z6: Not Defined in Source | AA6: Cited among the operating exceptions supporting the Partially Effective conclusion (§10) | AB6: Simulated portfolio scenario
A7: FRT-003 | B7: ACR-02 | C7: MAL-ACR-002 | D7: User Access Review Worksheet | E7: §8–9 | F7: CTL-mu1nugzu — Restrict AI training data repositories to authorized personnel using role-based access (NIST CSF PR.AA-05) | G7: Partially Effective | H7: AST-002 (source ID AST-mu0set5n) — Financial Risk Training Data Repository | I7: RSK-mu0t1uva (RSK-002) — Unauthorized user exploits inadequate data access restrictions causing sensitive data exposure to Financial Risk Training Data Repository | J7: ACR-02 — Excessive Write Privileges (Least Privilege) | K7: Generic test identities U-1101 and U-1102 were assigned a write/modify role (FRTDR-DataEngineer) although their job function requires read-only (FRTDR-DataScientist) access. (Simulated.) | L7: Confirmed Finding (Simulated) | M7: Control Deficiency (Exception) | N7: Medium-High | O7: Medium-High | P7: IAM Team (execution), with Data Science Team (resource-owner approval) | Q7: IAM Team | R7: Downgrade both accounts to read-only; enforce the authoritative role-to-entitlement mapping; require documented business justification and periodic recertification for any write-level access. | S7: In Progress (Simulated) | T7: In Progress (Simulated) | U7: Not performed — evidence not provided | V7: October 31, 2026 (Simulated) | W7: 46326 | X7: Exact date | Y7: Control-level evidence list EVD-006 to EVD-011 (Evidence Requests tab); the source does not map items to this record | Z7: Not Defined in Source | AA7: Cited among the operating exceptions supporting the Partially Effective conclusion (§10) | AB7: Simulated portfolio scenario
A8: FRT-004 | B8: ACR-03 | C8: MAL-ACR-002 | D8: User Access Review Worksheet | E8: §8–9 | F8: CTL-mu1nugzu — Restrict AI training data repositories to authorized personnel using role-based access (NIST CSF PR.AA-05) | G8: Partially Effective | H8: AST-002 (source ID AST-mu0set5n) — Financial Risk Training Data Repository | I8: RSK-mu0t1uva (RSK-002) — Unauthorized user exploits inadequate data access restrictions causing sensitive data exposure to Financial Risk Training Data Repository | J8: ACR-03 — Delayed Contractor Deprovisioning (Leaver) | K8: Contractor test identity C-207 remained active for approximately 12 days after the contract end date, exceeding the same-business-day deprovisioning expectation for departed personnel. (Simulated.) | L8: Confirmed Finding (Simulated) | M8: Control Deficiency (Exception) | N8: High (window) | O8: High | P8: IAM Team (execution), with HR / Vendor Management (notification of end dates) | Q8: IAM Team | R8: Implement event-driven deprovisioning tied to contract end dates; perform leaver reconciliation each quarter; generate alerts for any account active past its associated end date. | S8: Remediated (Simulated) — account disabled; underlying process fix Open | T8: Reported Remediated (Sim.) — Process Fix Open | U8: Not performed — evidence not provided | V8: November 15, 2026 (Simulated) for the process fix | W8: 46341 | X8: Exact date | Y8: Control-level evidence list EVD-006 to EVD-011 (Evidence Requests tab); the source does not map items to this record | Z8: Not Defined in Source | AA8: Cited among the operating exceptions supporting the Partially Effective conclusion (§10) | AB8: Simulated portfolio scenario
A9: FRT-005 | B9: OBS-01 | C9: MAL-CTW-003 | D9: Change Management Control Test Worksheet | E9: §9 | F9: CTL-mu1nvfmw — Require documented review and approval before production AI model changes are deployed (SOC 2 CC8.1) | G9: Effective | H9: AST-001 — Clinical Diagnostic AI Model (change record CHG-2058) | I9: RSK-mu0t2oau (RSK-003) — Unauthorized developer exploits excessive privileges causing unapproved model changes to AI Model Training Server (linked on theme); secondary risk with no risk ID in source, referenced by title: “Incomplete validation exploits insufficient testing coverage causing defective models to advance from Pre-Production AI Validation Environment” | J9: OBS-01 — Rollback-Plan Documentation (Process-Improvement Observation) | K9: For change CHG-2058, the rollback-plan section of the change record was present but lacked sufficient detail. (Simulated.) | L9: Observation | M9: Process-Improvement Observation | N9: Not separately rated; Risk / Impact: Low | O9: Low | P9: AI Engineering Team | Q9: AI Engineering Team | R9: Adopt a standardized rollback-plan template within the change record so that rollback steps are consistently documented in sufficient detail. | S9: Open (Simulated) — process improvement | T9: Open (Simulated) | U9: Not performed — evidence not provided | V9: October 31, 2026 (Simulated) | W9: 46326 | X9: Exact date | Y9: Control-level evidence list EVD-012 to EVD-018 (Evidence Requests tab); the source does not map items to this record | Z9: Not Defined in Source | AA9: Process-improvement observation — not a control exception; does not affect the attribute results or the Effective rating. | AB9: Simulated portfolio scenario
A10: FRT-006 | B10: OBS-01 | C10: MAL-STD-004 | D10: Privileged Access & Multi-Factor Authentication Security Standard | E10: §9 | F10: CTL-004 — Enforce multi-factor authentication and least-privilege access for privileged AI platform accounts (CIS 6) | G10: Effective | H10: AST-001, AST-002, AST-003, AST-004, AST-006, AST-007, AST-008, AST-009, AST-010 (in-scope assets per MAL-STD-004 §3) | I10: RSK-mu0t2oau (RSK-003) — primary risk mitigated by this control (source-provided) | J10: OBS-01 — Break-Glass Review Cadence (Minor) | K10: The standard requires controlled emergency / break-glass access (§7.5), but a specific periodic review cadence for break-glass account usage has not yet been formally defined. | L10: Observation | M10: Process-Improvement Observation | N10: Not separately rated; Risk / Impact: Low | O10: Low | P10: IAM Team | Q10: IAM Team | R10: Establish a documented quarterly review of break-glass account activity, with review ownership, evidence retention, and escalation requirements. | S10: Open (Simulated) | T10: Open (Simulated) | U10: Not performed — evidence not provided | V10: Q4 2026 | X10: Quarter (text) | Y10: Control-level evidence list EVD-019 to EVD-027 (Evidence Requests tab); the source does not map items to this record | Z10: Verify the review requirement and supporting evidence during the next quarterly conformance assessment. | AA10: Not a control exception or a finding; does not change the Effective rating recorded in the Control Register. | AB10: Simulated portfolio scenario
A11: FRT-007 | B11: VUL-01 | C11: MAL-VMA-005 | D11: Vulnerability Management Control Assessment / Test Report | E11: §10–11 | F11: CTL-005 — Perform vulnerability testing and remediate identified weaknesses in production AI APIs (NIST CSF DE.CM-09) | G11: Partially Effective | H11: AST-001 — Clinical Diagnostic AI Model | I11: RSK-004 and RSK-006 (nearest related risks; imperfect mapping — see Section 5 coverage gap) | J11: VUL-01 — Scan Coverage Gap (Finding) | K11: Authenticated monthly scanning is established for the in-scope production AI service, but the API/endpoint inventory is not consistently reconciled to the scan scope, so one or more production endpoints associated with AST-001 may be omitted from a given monthly cycle. (Simulated.) | L11: Confirmed Finding (Simulated) | M11: Control Deficiency (Finding) | N11: Medium | O11: Medium | P11: Application Security Team (execution), with Clinical AI & Machine Learning Team (asset-owner support) | Q11: Application Security Team | R11: Reconcile the API/endpoint inventory to the authenticated scan scope each monthly cycle and add a coverage-completeness check that flags any production endpoint not covered by a scan in the period. | S11: In Progress (Simulated) | T11: In Progress (Simulated) | U11: Not performed — evidence not provided | V11: November 30, 2026 (Simulated) | W11: 46356 | X11: Exact date | Y11: Control-level evidence list EVD-028 to EVD-034 (Evidence Requests tab); the source does not map items to this record | Z11: Re-confirm scope-to-inventory reconciliation and coverage evidence at the next monthly assessment. | AA11: Rating rests primarily on VUL-01 and VUL-02 (Partially Effective) | AB11: Simulated portfolio scenario
A12: FRT-008 | B12: VUL-02 | C12: MAL-VMA-005 | D12: Vulnerability Management Control Assessment / Test Report | E12: §10–11 | F12: CTL-005 — Perform vulnerability testing and remediate identified weaknesses in production AI APIs (NIST CSF DE.CM-09) | G12: Partially Effective | H12: AST-001 — Clinical Diagnostic AI Model | I12: RSK-004 and RSK-006 (nearest related risks; imperfect mapping — see Section 5 coverage gap) | J12: VUL-02 — Remediation Timeliness (Finding) | K12: Identified vulnerabilities are tracked and risk-rated, but remediation SLA adherence is inconsistent: a subset of findings — including at least one higher-severity finding — exceeded their defined remediation windows before closure. (Simulated.) | L12: Confirmed Finding (Simulated) | M12: Control Deficiency (Finding) | N12: Medium | O12: Medium | P12: Application Security Team (tracking), with Clinical AI & Machine Learning Team (accountable for remediation) and AI Engineering Team (fixes) | Q12: Application Security Team | R12: Enforce severity-based remediation SLAs, escalate overdue items to the asset owner and management, and report SLA-adherence metrics on the control’s monthly cadence. | S12: In Progress (Simulated) | T12: In Progress (Simulated) | U12: Not performed — evidence not provided | V12: November 30, 2026 (Simulated) | W12: 46356 | X12: Exact date | Y12: Control-level evidence list EVD-028 to EVD-034 (Evidence Requests tab); the source does not map items to this record | Z12: Review SLA-adherence metrics and overdue-item aging at the next monthly assessment. | AA12: Rating rests primarily on VUL-01 and VUL-02 (Partially Effective) | AB12: Simulated portfolio scenario
A13: FRT-009 | B13: VUL-03 | C13: MAL-VMA-005 | D13: Vulnerability Management Control Assessment / Test Report | E13: §10–11 | F13: CTL-005 — Perform vulnerability testing and remediate identified weaknesses in production AI APIs (NIST CSF DE.CM-09) | G13: Partially Effective | H13: AST-001 — Clinical Diagnostic AI Model | I13: RSK-004 and RSK-006 (nearest related risks; imperfect mapping — see Section 5 coverage gap) | J13: VUL-03 — AI-Specific Security Testing Gap (Observation) | K13: Conventional web/API vulnerability testing is performed, but the testing program does not yet include AI-specific abuse cases (for example, input/prompt validation and model-inference abuse) for the production AI API. (Simulated.) | L13: Observation | M13: Process-Improvement Observation | N13: Low (Observation) | O13: Low | P13: Application Security Team | Q13: Application Security Team | R13: Extend the testing program to include AI/LLM-specific test cases for production AI APIs, aligned to emerging AI-security testing guidance; pilot on the in-scope service first. | S13: Open (Simulated) | T13: Open (Simulated) | U13: Not performed — evidence not provided | V13: Q4 2026 (Simulated) | X13: Quarter (text) | Y13: Control-level evidence list EVD-028 to EVD-034 (Evidence Requests tab); the source does not map items to this record | Z13: Confirm AI-specific test cases and results at a subsequent assessment. | AA13: Contributes context; the Partially Effective rating rests primarily on VUL-01 and VUL-02. | AB13: Simulated portfolio scenario
A14: FRT-010 | B14: None assigned in source | C14: MAL-VMA-005 | D14: Vulnerability Management Control Assessment / Test Report | E14: §5 | F14: CTL-005 — Perform vulnerability testing and remediate identified weaknesses in production AI APIs (NIST CSF DE.CM-09) | G14: Partially Effective | H14: AST-001 — Clinical Diagnostic AI Model (control's in-scope asset) | I14: None in register (coverage gap); nearest related: RSK-004 and RSK-006 | J14: Risk-Register Coverage Gap — Exploitable Vulnerabilities in Production AI APIs | K14: No risk record in the register specifically addresses exploitable vulnerabilities in production AI APIs — the exact exposure this control mitigates. This is a risk-register coverage gap: the control operates against a risk that is not explicitly represented in the register. | L14: Observation | M14: Risk-Register Coverage Gap | N14: Not rated in source | O14: Not Rated | P14: Application Security Team (proposed owner of the recommended risk record) | Q14: Application Security Team | R14: Add a risk record for “exploitable vulnerabilities in production AI APIs” (owner Application Security Team) and link CTL-005 to it. | S14: Not stated in source | T14: No Status in Source | U14: Not performed — evidence not provided | V14: Not stated in source | X14: Not stated in source | Y14: Control-level evidence list EVD-028 to EVD-034 (Evidence Requests tab); the source does not map items to this record | Z14: Not Defined in Source | AA14: Described in source as an observation carried to the consolidated tracker; no rating impact stated. | AB14: Simulated portfolio scenario
A15: FRT-011 | B15: PRV-01 | C15: MAL-PIA-006 | D15: AI Privacy Impact Assessment (DPIA-Aligned) | E15: §11–12 | F15: CTL-006 — Review AI datasets for unnecessary personal information and apply privacy safeguards before processing (GDPR Art.5) | G15: Partially Effective | H15: AST-002 (Stream A — financial training data); AST-001 and AST-009 (Stream B — clinical processing) | I15: RSK-002 (Stream A) and RSK-008 (Stream B) — nearest related risks; imperfect, “loosely related” mapping (see Section 5 coverage gap) | J15: PRV-01 — Data Minimization Gap (Finding) | K15: The assessment scenario indicates that the quarterly minimization review does not consistently document whether all retained personal-data elements are necessary for the stated processing purpose; unnecessary personal data may therefore be retained without a documented justification. Applies across Stream A (AST-002) and the clinical Stream B (AST-001 / AST-009). | L15: Confirmed Finding (Simulated) | M15: Control Deficiency (Finding) | N15: Medium | O15: Medium | P15: Privacy and Compliance Team (review), with Data Science Team and Clinical AI & Machine Learning Team (asset owners) | Q15: Privacy and Compliance Team | R15: For each in-scope dataset, maintain a data inventory mapping every personal-data element to a documented necessity justification tied to the processing purpose; remove or justify elements that are not necessary; record decisions each review cycle. | S15: In Progress (Simulated) | T15: In Progress (Simulated) | U15: Not performed — evidence not provided | V15: December 31, 2026 (Simulated) | W15: 46387 | X15: Exact date | Y15: Control-level evidence list EVD-035 to EVD-041 (Evidence Requests tab); the source does not map items to this record | Z15: Re-confirm the documented necessity mapping and minimization decisions at the next quarterly review. | AA15: Rating rests primarily on PRV-01 and PRV-02 (Partially Effective) | AB15: Simulated portfolio scenario
A16: FRT-012 | B16: PRV-02 | C16: MAL-PIA-006 | D16: AI Privacy Impact Assessment (DPIA-Aligned) | E16: §11–12 | F16: CTL-006 — Review AI datasets for unnecessary personal information and apply privacy safeguards before processing (GDPR Art.5) | G16: Partially Effective | H16: AST-002 (Stream A — financial training data); AST-001 and AST-009 (Stream B — clinical processing) | I16: RSK-002 (Stream A) and RSK-008 (Stream B) — nearest related risks; imperfect, “loosely related” mapping (see Section 5 coverage gap) | J16: PRV-02 — Inconsistent Privacy Safeguards (Finding) | K16: The assessment scenario indicates that privacy safeguards (for example, masking or pseudonymization of personal-data elements) are not consistently applied across all in-scope personal data before processing, and that the application of safeguards is not uniformly documented. | L16: Confirmed Finding (Simulated) | M16: Control Deficiency (Finding) | N16: Medium | O16: Medium | P16: Privacy and Compliance Team (standard), with Data Science Team / AI Engineering Team (implementation) and Data Protection Team (clinical backup) | Q16: Privacy and Compliance Team | R16: Define a consistent safeguard standard (masking / pseudonymization and access restriction) for personal-data elements before processing, apply it across all in-scope datasets, and record the safeguards applied per dataset. | S16: In Progress (Simulated) | T16: In Progress (Simulated) | U16: Not performed — evidence not provided | V16: December 31, 2026 (Simulated) | W16: 46387 | X16: Exact date | Y16: Control-level evidence list EVD-035 to EVD-041 (Evidence Requests tab); the source does not map items to this record | Z16: Review safeguard-application records per dataset at the next quarterly review. | AA16: Rating rests primarily on PRV-01 and PRV-02 (Partially Effective) | AB16: Simulated portfolio scenario
A17: FRT-013 | B17: PRV-03 | C17: MAL-PIA-006 | D17: AI Privacy Impact Assessment (DPIA-Aligned) | E17: §11–12 | F17: CTL-006 — Review AI datasets for unnecessary personal information and apply privacy safeguards before processing (GDPR Art.5) | G17: Partially Effective | H17: AST-002 (Stream A — financial training data); AST-001 and AST-009 (Stream B — clinical processing) | I17: RSK-002 (Stream A) and RSK-008 (Stream B) — nearest related risks; imperfect, “loosely related” mapping (see Section 5 coverage gap) | J17: PRV-03 — Retention / Storage Limitation (Observation) | K17: The assessment scenario indicates that retention periods for personal data in the in-scope datasets are not yet formally defined or enforced, so data could be retained longer than necessary. | L17: Observation | M17: Process-Improvement Observation | N17: Low (Observation) | O17: Low | P17: Privacy and Compliance Team | Q17: Privacy and Compliance Team | R17: Define retention periods for personal data in each in-scope dataset aligned to the processing purpose, implement periodic deletion / review, and formalize a retention schedule. | S17: Open (Simulated) | T17: Open (Simulated) | U17: Not performed — evidence not provided | V17: Q1 2027 (Simulated) | X17: Quarter (text) | Y17: Control-level evidence list EVD-035 to EVD-041 (Evidence Requests tab); the source does not map items to this record | Z17: Confirm the retention schedule and enforcement evidence at a subsequent review. | AA17: Contributes context; the Partially Effective rating rests primarily on PRV-01 and PRV-02. | AB17: Simulated portfolio scenario
A18: FRT-014 | B18: None assigned in source | C18: MAL-PIA-006 | D18: AI Privacy Impact Assessment (DPIA-Aligned) | E18: §5 | F18: CTL-006 — Review AI datasets for unnecessary personal information and apply privacy safeguards before processing (GDPR Art.5) | G18: Partially Effective | H18: AST-002; AST-001; AST-009 (in-scope streams) | I18: None in register (coverage gap); nearest related: RSK-002 and RSK-008 | J18: Risk-Register Coverage Gap — Unnecessary Personal Data / Non-Compliant Processing in AI Datasets | K18: No risk record in the register specifically addresses excessive or unnecessary personal data in AI datasets, or non-compliant processing of personal data — the exact exposure this control mitigates. This is a risk-register coverage gap: the control operates against a risk that is not explicitly represented in the register. | L18: Observation | M18: Risk-Register Coverage Gap | N18: Not rated in source | O18: Not Rated | P18: Privacy and Compliance Team (proposed owner of the recommended risk record) | Q18: Privacy and Compliance Team | R18: Add a risk record for “unnecessary personal data / non-compliant processing in AI datasets” (owner Privacy and Compliance Team) and link CTL-006 to it. | S18: Not stated in source | T18: No Status in Source | U18: Not performed — evidence not provided | V18: Not stated in source | X18: Not stated in source | Y18: Control-level evidence list EVD-035 to EVD-041 (Evidence Requests tab); the source does not map items to this record | Z18: Not Defined in Source | AA18: Described in source as an observation carried to the consolidated tracker; no rating impact stated. | AB18: Simulated portfolio scenario
A19: FRT-015 | B19: OBS-01 | C19: MAL-BRT-007 | D19: Backup & Recovery Test Record | E19: §10 | F19: CTL-007 — Maintain tested backup and recovery procedures for critical production AI systems (ISO 27001 A.5.30) | G19: Effective | H19: AST-001 (protected system); AST-009 (backup source); AST-010 (recovery environment) | I19: RSK-007 — Infrastructure outage exploits inadequate recovery testing causing prolonged service disruption to AI Disaster Recovery Cloud Environment (primary risk; direct fit — no coverage gap claimed) | J19: OBS-01 — RTO/RPO Metrics Documentation (Low / Process-Improvement Observation) | K19: Within the simulated test scenario, recovery testing is represented as successfully completed; however, the test-record design does not include a standardized field for documenting formally approved RTO / RPO targets alongside measured recovery outcomes. | L19: Observation | M19: Process-Improvement Observation | N19: Low | O19: Low | P19: Infrastructure Operations Team | Q19: Infrastructure Operations Team | R19: Add standardized RTO / RPO target and actual-result fields to future quarterly recovery test records to strengthen repeatability, trend analysis, and management reporting. | S19: Open (Simulated) | T19: Open (Simulated) | U19: Not performed — evidence not provided | V19: Q1 2027 (Simulated) | X19: Quarter (text) | Y19: Control-level evidence list EVD-042 to EVD-049 (Evidence Requests tab); the source does not map items to this record | Z19: Confirm the enhanced RTO / RPO fields are present in the next quarterly recovery test record. | AA19: None; this is a process-improvement observation and does not affect the Effective rating. | AB19: Simulated portfolio scenario
A20: FRT-016 | B20: LOG-01 | C20: MAL-LMA-008 | D20: Security Logging & Monitoring Control Assessment | E20: §10–11 | F20: CTL-008 — Centralize and review security logs for suspicious activity affecting production AI systems (CIS 8) | G20: Partially Effective | H20: AST-001, AST-002, AST-007 (log sources); central logging capability has no distinct asset | I20: RSK-006 — nearest register risk, with mapping limitation (network-access risk); RSK-002 and RSK-003 noted as detection scenarios only | J20: LOG-01 — Log Source Coverage Gap (Finding) | K20: The assessment scenario indicates that not all in-scope production AI systems consistently forward their security logs to the central logging capability; at least one in-scope source appears incompletely onboarded, so some security events may not reach central logging for review. | L20: Confirmed Finding (Simulated) | M20: Control Deficiency (Finding) | N20: Medium | O20: Medium | P20: Security Operations Team (central logging), with the relevant log-source / asset owners | Q20: Security Operations Team | R20: Reconcile the in-scope production AI systems to the central logging source inventory; onboard any missing source; add a periodic coverage-completeness check that flags any in-scope system not forwarding logs. | S20: In Progress (Simulated) | T20: In Progress (Simulated) | U20: Not performed — evidence not provided | V20: December 31, 2026 (Simulated) | W20: 46387 | X20: Exact date | Y20: Control-level evidence list EVD-050 to EVD-057 (Evidence Requests tab); the source does not map items to this record | Z20: Re-confirm source-to-inventory reconciliation and coverage evidence at the next review. | AA20: Conclusion driven primarily by LOG-01 and LOG-02 (Partially Effective) | AB20: Simulated portfolio scenario
A21: FRT-017 | B21: LOG-02 | C21: MAL-LMA-008 | D21: Security Logging & Monitoring Control Assessment | E21: §10–11 | F21: CTL-008 — Centralize and review security logs for suspicious activity affecting production AI systems (CIS 8) | G21: Partially Effective | H21: AST-001, AST-002, AST-007 (log sources); central logging capability has no distinct asset | I21: RSK-006 — nearest register risk, with mapping limitation (network-access risk); RSK-002 and RSK-003 noted as detection scenarios only | J21: LOG-02 — Log Review / Alert-Triage Timeliness (Finding) | K21: The assessment scenario indicates that although logs are centralized, continuous review and alert triage are not consistently performed within a defined timeframe, and alerting thresholds for AI-relevant suspicious activity are not fully established. | L21: Confirmed Finding (Simulated) | M21: Control Deficiency (Finding) | N21: Medium | O21: Medium | P21: Security Operations Team | Q21: Security Operations Team | R21: Define review / triage timeframes and alerting thresholds for suspicious activity on in-scope systems; document who reviews, how often, and escalation paths; report review / triage timeliness metrics. | S21: In Progress (Simulated) | T21: In Progress (Simulated) | U21: Not performed — evidence not provided | V21: December 31, 2026 (Simulated) | W21: 46387 | X21: Exact date | Y21: Control-level evidence list EVD-050 to EVD-057 (Evidence Requests tab); the source does not map items to this record | Z21: Review triage-timeliness metrics and alerting configuration at the next review. | AA21: Conclusion driven primarily by LOG-01 and LOG-02 (Partially Effective) | AB21: Simulated portfolio scenario
A22: FRT-018 | B22: LOG-03 | C22: MAL-LMA-008 | D22: Security Logging & Monitoring Control Assessment | E22: §10–11 | F22: CTL-008 — Centralize and review security logs for suspicious activity affecting production AI systems (CIS 8) | G22: Partially Effective | H22: AST-001, AST-002, AST-007 (log sources); central logging capability has no distinct asset | I22: RSK-006 — nearest register risk, with mapping limitation (network-access risk); RSK-002 and RSK-003 noted as detection scenarios only | J22: LOG-03 — AI-Specific Detection Use-Case Maturity (Observation) | K22: The assessment scenario indicates that general security monitoring is established, but AI-specific detection use cases, such as anomalous model API access, unusual model-administration activity, or unexpected access patterns affecting AI data repositories, are not yet formally defined across the monitoring program. | L22: Observation | M22: Process-Improvement Observation | N22: Low (Observation) | O22: Low | P22: Security Operations Team | Q22: Security Operations Team | R22: Define and document prioritized AI-specific detection use cases for critical and high-classification production AI systems and incorporate them into the monitoring program’s detection and review procedures. | S22: Open (Simulated) | T22: Open (Simulated) | U22: Not performed — evidence not provided | V22: Q1 2027 (Simulated) | X22: Quarter (text) | Y22: Control-level evidence list EVD-050 to EVD-057 (Evidence Requests tab); the source does not map items to this record | Z22: Confirm defined AI-specific detection use-cases and their incorporation at a subsequent review. | AA22: None independently. The Partially Effective conclusion is driven primarily by LOG-01 and LOG-02. | AB22: Simulated portfolio scenario
A23: FRT-019 | B23: None assigned in source | C23: MAL-LMA-008 | D23: Security Logging & Monitoring Control Assessment | E23: §5 | F23: CTL-008 — Centralize and review security logs for suspicious activity affecting production AI systems (CIS 8) | G23: Partially Effective | H23: AST-001, AST-002, AST-007 (log sources in scope) | I23: None in register (coverage gap); nearest related: RSK-006 | J23: Risk-Register Coverage Gap — Undetected Suspicious Activity on Production AI Systems | K23: No current Risk Register entry specifically represents the risk that suspicious or malicious activity affecting production AI systems remains undetected because security logs are incomplete, not centralized, or inadequately reviewed. | L23: Observation | M23: Risk-Register Coverage Gap | N23: Not rated in source | O23: Not Rated | P23: Security Operations Team (proposed owner of the recommended risk record) | Q23: Security Operations Team | R23: Add such a risk (owner Security Operations Team) and link CTL-008 to it. | S23: Not stated in source | T23: No Status in Source | U23: Not performed — evidence not provided | V23: Not stated in source | X23: Not stated in source | Y23: Control-level evidence list EVD-050 to EVD-057 (Evidence Requests tab); the source does not map items to this record | Z23: Not Defined in Source | AA23: Described in source as an observation carried to the consolidated tracker; no rating impact stated. | AB23: Simulated portfolio scenario
A24: FRT-020 | B24: None assigned in source | C24: MAL-LMA-008 | D24: Security Logging & Monitoring Control Assessment | E24: §3 | F24: CTL-008 — Centralize and review security logs for suspicious activity affecting production AI systems (CIS 8) | G24: Partially Effective | H24: None — no distinct central logging / SIEM platform in the Asset Register | I24: None stated | J24: Asset-Register Traceability Observation — No Central Logging Platform Identified | K24: CTL-008 requires centralized security logging, but the current Asset Register does not identify a distinct central logging or SIEM platform. This assessment therefore evaluates the centralized logging capability as a control function operated by the Security Operations Team without assigning an unsupported platform or asset identifier. | L24: Observation | M24: Asset-Register Observation | N24: Not rated in source | O24: Not Rated | P24: Not specified in source | Q24: Not specified in source | R24: Consider adding the central logging platform to the Asset Register if it is maintained as a separately managed information asset. | S24: Not stated in source | T24: No Status in Source | U24: Not performed — evidence not provided | V24: Not stated in source | X24: Not stated in source | Y24: Control-level evidence list EVD-050 to EVD-057 (Evidence Requests tab); the source does not map items to this record | Z24: Not Defined in Source | AA24: Described in source as an observation carried to the consolidated tracker; no rating impact stated. | AB24: Simulated portfolio scenario
A25: FRT-021 | B25: APO-01 | C25: MAL-CAP-009 | D25: Compliance Assessment Plan & Evidence Request | E25: §11 | F25: CTL-009 — Perform documented compliance assessments of high-impact AI systems against applicable requirements (ISO 27001 A.5.31) | G25: Not Tested | H25: AST-001 (primary), AST-002 (supporting), AST-006 (reference only) — per MAL-CAP-009 §3 | I25: No dedicated risk in register; nearest (imperfect) risk referenced by title only: “Incomplete validation exploits insufficient testing coverage causing defective models to advance from Pre-Production AI Validation Environment” | J25: APO-01 — Incomplete Control Documentation | K25: The source control record does not expose a description or rationale, and the register does not define “high-impact AI system.” | L25: Planning Gap | M25: Planning Observation | N25: Not rated in source | O25: Not Rated | P25: Not specified in source | Q25: Not specified in source | R25: Confirm the authoritative control description, high-impact definition, and expected evidence before testing. | S25: Not stated in source | T25: No Status in Source | U25: Not performed — evidence not provided | V25: Not stated in source | X25: Not stated in source | Y25: Not specified in source — PBC list (EVD-058 to EVD-069) is control-level; the source does not map PBC items to planning observations | Z25: Not Defined in Source | AA25: None — planning observation, not a finding or control deficiency; no effectiveness conclusion drawn (Not Concluded). | AB25: Simulated portfolio scenario
A26: FRT-022 | B26: APO-02 | C26: MAL-CAP-009 | D26: Compliance Assessment Plan & Evidence Request | E26: §11 | F26: CTL-009 — Perform documented compliance assessments of high-impact AI systems against applicable requirements (ISO 27001 A.5.31) | G26: Not Tested | H26: AST-001 (primary), AST-002 (supporting), AST-006 (reference only) — per MAL-CAP-009 §3 | I26: No dedicated risk in register; nearest (imperfect) risk referenced by title only: “Incomplete validation exploits insufficient testing coverage causing defective models to advance from Pre-Production AI Validation Environment” | J26: APO-02 — Responsible AI Policy Not Finalized | K26: POL-006 (Responsible AI and Human Oversight Policy) has a source status of Under Review. | L26: Planning Gap | M26: Planning Observation | N26: Not rated in source | O26: Not Rated | P26: Not specified in source | Q26: Not specified in source | R26: Confirm the approved version and status before using it as formal assessment criteria. | S26: Not stated in source | T26: No Status in Source | U26: Not performed — evidence not provided | V26: Not stated in source | X26: Not stated in source | Y26: Not specified in source — PBC list (EVD-058 to EVD-069) is control-level; the source does not map PBC items to planning observations | Z26: Not Defined in Source | AA26: None — planning observation, not a finding or control deficiency; no effectiveness conclusion drawn (Not Concluded). | AB26: Simulated portfolio scenario
A27: FRT-023 | B27: APO-03 | C27: MAL-CAP-009 | D27: Compliance Assessment Plan & Evidence Request | E27: §11 (see also §6.2) | F27: CTL-009 — Perform documented compliance assessments of high-impact AI systems against applicable requirements (ISO 27001 A.5.31) | G27: Not Tested | H27: AST-001 (primary), AST-002 (supporting), AST-006 (reference only) — per MAL-CAP-009 §3 | I27: No dedicated risk in register; nearest (imperfect) risk referenced by title only: “Incomplete validation exploits insufficient testing coverage causing defective models to advance from Pre-Production AI Validation Environment” | J27: APO-03 — Compliance Risk Coverage Gap | K27: No dedicated risk addresses failure to assess high-impact AI systems against applicable requirements. | L27: Planning Gap | M27: Planning Observation | N27: Not rated in source | O27: Not Rated | P27: GRC Team (proposed owner of the recommended risk record) | Q27: GRC Team | R27: Consider a dedicated compliance risk owned by the GRC Team, linked to CTL-009. Carry to the Findings & Remediation Tracker. | S27: Not stated in source | T27: No Status in Source | U27: Not performed — evidence not provided | V27: Not stated in source | X27: Not stated in source | Y27: Not specified in source — PBC list (EVD-058 to EVD-069) is control-level; the source does not map PBC items to planning observations | Z27: Not Defined in Source | AA27: None — planning observation, not a finding or control deficiency; no effectiveness conclusion drawn (Not Concluded). | AB27: Simulated portfolio scenario
A28: FRT-024 | B28: APO-04 | C28: MAL-CAP-009 | D28: Compliance Assessment Plan & Evidence Request | E28: §11 (see also §6.3) | F28: CTL-009 — Perform documented compliance assessments of high-impact AI systems against applicable requirements (ISO 27001 A.5.31) | G28: Not Tested | H28: AST-001 (primary), AST-002 (supporting), AST-006 (reference only) — per MAL-CAP-009 §3 | I28: No dedicated risk in register; nearest (imperfect) risk referenced by title only: “Incomplete validation exploits insufficient testing coverage causing defective models to advance from Pre-Production AI Validation Environment” | J28: APO-04 — Compliance Risk Appetite Coverage | K28: No dedicated Compliance appetite statement is represented in the available risk-appetite records. | L28: Planning Gap | M28: Planning Observation | N28: Not rated in source | O28: Not Rated | P28: Not specified in source | Q28: Not specified in source | R28: Confirm whether compliance risk is governed under another approved appetite category or whether a dedicated statement should be established. | S28: Not stated in source | T28: No Status in Source | U28: Not performed — evidence not provided | V28: Not stated in source | X28: Not stated in source | Y28: Not specified in source — PBC list (EVD-058 to EVD-069) is control-level; the source does not map PBC items to planning observations | Z28: Not Defined in Source | AA28: None — planning observation, not a finding or control deficiency; no effectiveness conclusion drawn (Not Concluded). | AB28: Simulated portfolio scenario
A29: FRT-025 | B29: VRA-01 | C29: MAL-VRA-010 | D29: Third-Party AI Vendor Risk Assessment | E29: §11–12 | F29: CTL-010 — Assess security and privacy risks before approving third-party AI vendors and services (SOC 2 CC9.2) | G29: Ineffective | H29: None established in source (no register asset is a vendor; AST-001 would be relevant only if a third-party AI service accessed it — no such relationship is asserted) | I29: No primary risk in register (coverage gap, §5.1); no vendor-to-risk linkage established in source | J29: VRA-01 — Pre-Approval Assessment Not Consistently Performed and Documented (Finding) | K29: The simulated scenario indicates that third-party AI vendors and services subject to approval during the assessment period can proceed to approval without a completed and documented security and privacy risk assessment, or with the assessment completed after the approval decision. (Simulated.) | L29: Confirmed Finding (Simulated) | M29: Control Deficiency (Finding) | N29: High | O29: High | P29: Third-Party Risk Management Team, with Privacy and Compliance Team support | Q29: Third-Party Risk Management Team | R29: Establish a mandatory pre-approval gate under which no vendor or service is approved or onboarded without a completed, documented security and privacy assessment and recorded sign-off. Assess retrospectively any approved vendors and services that lack an assessment, starting with those handling sensitive data. | S29: Open (Simulated) | T29: Open (Simulated) | U29: Not performed — evidence not provided | V29: November 30, 2026 (Simulated) | W29: 46356 | X29: Exact date | Y29: Source-stated via attribute mapping: EVD-074 (EV-05), EVD-075 (EV-06), EVD-076 (EV-07), EVD-077 (EV-08), EVD-078 (EV-09), EVD-079 (EV-10), EVD-080 (EV-11), EVD-081 (EV-12) | Z29: Re-perform against the approval population for the next assessment period and confirm every approval is preceded by a completed assessment. | AA29: Primary driver of the Ineffective conclusion. | AB29: Simulated portfolio scenario
A30: FRT-026 | B30: VRA-02 | C30: MAL-VRA-010 | D30: Third-Party AI Vendor Risk Assessment | E30: §11–12 | F30: CTL-010 — Assess security and privacy risks before approving third-party AI vendors and services (SOC 2 CC9.2) | G30: Ineffective | H30: None established in source (no register asset is a vendor; AST-001 would be relevant only if a third-party AI service accessed it — no such relationship is asserted) | I30: No primary risk in register (coverage gap, §5.1); no vendor-to-risk linkage established in source | J30: VRA-02 — Vendor Risk Assessment Criteria and Tiering Not Defined (Finding) | K30: The simulated scenario indicates that no defined vendor risk-tiering methodology or consistent security and privacy assessment criteria for AI vendors and services are in place, so assessment depth is not set by vendor criticality or data sensitivity. (Simulated.) | L30: Confirmed Finding (Simulated) | M30: Control Deficiency (Finding) | N30: Medium | O30: Medium | P30: Third-Party Risk Management Team, with Privacy and Compliance Team and Information Security Team consulted | Q30: Third-Party Risk Management Team | R30: Define a vendor tiering methodology and minimum security and privacy assessment criteria for AI services (for example, data handling, model and data-use terms, incident notification, and sub-processor use), with assessment depth tied to tier. | S30: Open (Simulated) | T30: Open (Simulated) | U30: Not performed — evidence not provided | V30: December 31, 2026 (Simulated) | W30: 46387 | X30: Exact date | Y30: Source-stated via attribute mapping: EVD-072 (EV-03), EVD-073 (EV-04) | Z30: Confirm the approved methodology and criteria are applied to new approval requests at the next assessment. | AA30: Contributing deficiency. | AB30: Simulated portfolio scenario
A31: FRT-027 | B31: VRA-03 | C31: MAL-VRA-010 | D31: Third-Party AI Vendor Risk Assessment | E31: §11–12 | F31: CTL-010 — Assess security and privacy risks before approving third-party AI vendors and services (SOC 2 CC9.2) | G31: Ineffective | H31: None established in source (no register asset is a vendor; AST-001 would be relevant only if a third-party AI service accessed it — no such relationship is asserted) | I31: No primary risk in register (coverage gap, §5.1); no vendor-to-risk linkage established in source | J31: VRA-03 — Third-Party Governance Documentation and Inventory Gap (Finding) | K31: The simulated scenario indicates that third-party AI governance is not supported by a documented third-party risk policy within the available Policy Register, and the available source records do not provide a vendor/service inventory from which the population subject to CTL-010 can be established. | L31: Confirmed Finding (Simulated) | M31: Control Deficiency (Finding) | N31: Medium | O31: Medium | P31: Third-Party Risk Management Team, with GRC Team support for policy governance | Q31: Third-Party Risk Management Team | R31: Establish documented third-party AI risk governance requirements and maintain an authoritative inventory of third-party AI vendors and services subject to security and privacy assessment. | S31: Open (Simulated) | T31: Open (Simulated) | U31: Not performed — evidence not provided | V31: December 31, 2026 (Simulated) | W31: 46387 | X31: Exact date | Y31: Source-stated via attribute mapping: EVD-070 (EV-01), EVD-071 (EV-02), EVD-074 (EV-05) | Z31: Confirm an approved policy and an inventory reconciled to the approval population. | AA31: Contributing design / governance deficiency. | AB31: Simulated portfolio scenario
